<?xml version='1.0' encoding='utf-8'?>
<robot name="ic_arm_wrist_component">

  <!-- Wrist Component - Simplified Cross Wrist -->
  <!-- Links: wrist_base, wrist_link1, wrist_link2 -->
  <!-- Joints: joint_alpha (α), joint_beta (β) -->

  <link name="wrist_base">
    <inertial>
      <origin xyz="0 0 0" rpy="0 0 0"/>
      <mass value="0.1"/>
      <inertia ixx="0.0001" ixy="0" ixz="0" iyy="0.0001" iyz="0" izz="0.0001"/>
    </inertial>
    <visual>
      <origin xyz="0 0 0" rpy="0 0 0"/>
      <geometry>
        <cylinder radius="0.02" length="0.01"/>
      </geometry>
      <material name="">
        <color rgba="0.5 0.5 0.5 1"/>
      </material>
    </visual>
    <collision>
      <origin xyz="0 0 0" rpy="0 0 0"/>
      <geometry>
        <cylinder radius="0.02" length="0.01"/>
      </geometry>
    </collision>
  </link>

  <link name="wrist_link1">
    <inertial>
      <origin xyz="0 0 0.02" rpy="0 0 0"/>
      <mass value="0.08"/>
      <inertia ixx="0.00005" ixy="0" ixz="0" iyy="0.00005" iyz="0" izz="0.00004"/>
    </inertial>
    <visual>
      <origin xyz="0 0 0.02" rpy="0 0 0"/>
      <geometry>
        <cylinder radius="0.015" length="0.04"/>
      </geometry>
      <material name="">
        <color rgba="0.2 0.8 0.2 1"/>
      </material>
    </visual>
    <collision>
      <origin xyz="0 0 0.02" rpy="0 0 0"/>
      <geometry>
        <cylinder radius="0.015" length="0.04"/>
      </geometry>
    </collision>
  </link>

  <link name="wrist_link2">
    <inertial>
      <origin xyz="0 0 0.015" rpy="0 0 0"/>
      <mass value="0.06"/>
      <inertia ixx="0.00003" ixy="0" ixz="0" iyy="0.00003" iyz="0" izz="0.00002"/>
    </inertial>
    <visual>
      <origin xyz="0 0 0.015" rpy="0 0 0"/>
      <geometry>
        <cylinder radius="0.012" length="0.03"/>
      </geometry>
      <material name="">
        <color rgba="0.2 0.2 0.8 1"/>
      </material>
    </visual>
    <collision>
      <origin xyz="0 0 0.015" rpy="0 0 0"/>
      <geometry>
        <cylinder radius="0.012" length="0.03"/>
      </geometry>
    </collision>
  </link>

  <!-- Joint: Alpha (Pitch) -->
  <joint name="joint_alpha" type="revolute">
    <origin xyz="0 0 0.005" rpy="0 0 0" />
    <parent link="wrist_base" />
    <child link="wrist_link1" />
    <axis xyz="0 1 0" />
    <limit lower="-1.57" upper="1.57" effort="30.0" velocity="3.14" />
    <dynamics damping="0.1" friction="0.1"/>
  </joint>

  <!-- Joint: Beta (Roll) -->
  <joint name="joint_beta" type="revolute">
    <origin xyz="0 0 0.04" rpy="0 0 0" />
    <parent link="wrist_link1" />
    <child link="wrist_link2" />
    <axis xyz="1 0 0" />
    <limit lower="-1.57" upper="1.57" effort="30.0" velocity="3.14" />
    <dynamics damping="0.1" friction="0.1"/>
  </joint>

</robot>